<?xml version="1.0"?>
<robot name="robot_arm">
    <link name="base_link"/>
    <link name="simple_box">
        <visual>
            <geometry>
                <box size="1 1 1"/>
            </geometry>
        </visual>
        <origin xyz="0 0 0" rpy="0 0 0"/>
    </link>
    <joint name="base_box" type="prismatic">
        <parent link="base_link"/>
        <child link="simple_box"/>
        <origin xyz="0 0 0" rpy="0 0 0"/>
        <limit lower="-1" upper="1" effort="100" velocity="0.1"/>
    </joint>
</robot>